Workbook

Sheet Cover
B2: Reconciliation & Verification Tool
B3: Indian Tax & Compliance Rule Book for CA Firms – v2
B5: Appbay Technologies — reconciliation rules, statutory rules and document data model, YAML-ready
B9: Research date | C9: 13 October 2026
B10: Applicable tax period | C10: FY 2025-26 / AY 2026-27 (Income-tax Act, 1961) and Tax Year 2026-27 (Income-tax Act, 2025, in force from 1 April 2026); GST, payroll and company-law positions as at 13 Oct 2026
B11: Reconciliation rules | C11: =Contents!D6+Contents!D7+Contents!D8+Contents!D9 -> 90
B12: Statutory rules | C12: =Contents!D11+Contents!D12+Contents!D13+Contents!D14+Contents!D15+Contents!D16+Contents!D17+Contents!D18+Contents!D19+Contents!D20+Contents!D21+Contents!D22+Contents!D23+Contents!D24 -> 214
B13: Rules verified on an official source | C13: =Contents!E25 -> 77
B14: Documents / fields in data model | C14: 63 documents / 2096 fields
B15: How to read | C15: Start at Contents. Section A holds document-vs-document reconciliation rules; section B the statutory rules they rely on; section C the document data model and references. Row 5 of every rule sheet is the YAML key row.
B17: Verification status legend
B18: Verified – official source | C18: Key figures confirmed on an official government / regulator site
B19: Verified – secondary source only | C19: Confirmed on reputable secondary sources; official text not reached
B20: Partially verified | C20: Core rule confirmed; some element unconfirmed, or design choices involved
B21: Unverified – needs CA review | C21: Could not be confirmed – do not enable without CA review
B22: Ambiguous / conflicting – needs CA review | C22: Sources disagree or law reads ambiguously; positions recorded in Notes
B24: Important disclaimer
B25: This workbook is a research compilation to support software design. It is not legal or tax advice. Its completeness and legal correctness require validation by a qualified Chartered Accountant before any rule is implemented or relied on. Matching keys, tolerances and severities are implementation choices, not law. Laws, rates, thresholds and due dates change through Finance Acts, notifications and circulars; re-verify each rule for the period being processed. Rules not marked "Verified – official source" must be signed off in the Review Register before use.
B27: Go to Contents →

Sheet Contents
A1: Contents | J1: ← Contents
A2: Click a sheet name to open it. Counts are live formulas over each rule sheet.
A4: # | B4: Sheet | C4: What it contains | D4: Rules | E4: Verified – official | F4: Verified – secondary | G4: Partially verified | H4: Unverified | I4: Conflicting | J4: % official
B5: A. Reconciliation rules (document vs document)
A6: 1 | B6: Recon – GST | C6: Document-to-document GST reconciliation: sales register / e-invoice / e-way bill vs GSTR-1 vs GSTR-3B; purchase register vs GSTR-2B / IMS vs 3B Table 4; ledgers, interest, late fee, annual return, rate and place-of-supply checks. | D6: =COUNTA('Recon – GST'!A6:A2000) -> 40 | E6: =COUNTIF('Recon – GST'!E6:E2000,"Verified – official source") -> 0 | F6: =COUNTIF('Recon – GST'!E6:E2000,"Verified – secondary source only") -> 4 | G6: =COUNTIF('Recon – GST'!E6:E2000,"Partially verified") -> 30 | H6: =COUNTIF('Recon – GST'!E6:E2000,"Unverified – needs CA review") -> 6 | I6: =COUNTIF('Recon – GST'!E6:E2000,"Ambiguous / conflicting – needs CA review") -> 0 | J6: =IF(D6=0,0,E6/D6) -> 0
A7: 2 | B7: Recon – TDS & Income Tax | C7: Deductor-side TDS (ledger vs returns vs challans vs TRACES) and deductee-side income tax (26AS / AIS / TIS vs books vs ITR vs Form 3CD). | D7: =COUNTA('Recon – TDS & Income Tax'!A6:A2000) -> 25 | E7: =COUNTIF('Recon – TDS & Income Tax'!E6:E2000,"Verified – official source") -> 1 | F7: =COUNTIF('Recon – TDS & Income Tax'!E6:E2000,"Verified – secondary source only") -> 1 | G7: =COUNTIF('Recon – TDS & Income Tax'!E6:E2000,"Partially verified") -> 22 | H7: =COUNTIF('Recon – TDS & Income Tax'!E6:E2000,"Unverified – needs CA review") -> 1 | I7: =COUNTIF('Recon – TDS & Income Tax'!E6:E2000,"Ambiguous / conflicting – needs CA review") -> 0 | J7: =IF(D7=0,0,E7/D7) -> 0.04
A8: 3 | B8: Recon – Payroll | C8: Payroll register vs ECR vs EPF challan; ESIC; Professional Tax; payroll GL; s.36(1)(va); wage-definition, gratuity and bonus checks. | D8: =COUNTA('Recon – Payroll'!A6:A2000) -> 8 | E8: =COUNTIF('Recon – Payroll'!E6:E2000,"Verified – official source") -> 0 | F8: =COUNTIF('Recon – Payroll'!E6:E2000,"Verified – secondary source only") -> 3 | G8: =COUNTIF('Recon – Payroll'!E6:E2000,"Partially verified") -> 5 | H8: =COUNTIF('Recon – Payroll'!E6:E2000,"Unverified – needs CA review") -> 0 | I8: =COUNTIF('Recon – Payroll'!E6:E2000,"Ambiguous / conflicting – needs CA review") -> 0 | J8: =IF(D8=0,0,E8/D8) -> 0
A9: 4 | B9: Recon – Bank & Accounts | C9: Bank statement vs bank book (BRS), TB vs GL vs FS, ageing vs control accounts, FAR, stock statements, MSME, related parties, duplicates. | D9: =COUNTA('Recon – Bank & Accounts'!A6:A2000) -> 17 | E9: =COUNTIF('Recon – Bank & Accounts'!E6:E2000,"Verified – official source") -> 0 | F9: =COUNTIF('Recon – Bank & Accounts'!E6:E2000,"Verified – secondary source only") -> 4 | G9: =COUNTIF('Recon – Bank & Accounts'!E6:E2000,"Partially verified") -> 9 | H9: =COUNTIF('Recon – Bank & Accounts'!E6:E2000,"Unverified – needs CA review") -> 4 | I9: =COUNTIF('Recon – Bank & Accounts'!E6:E2000,"Ambiguous / conflicting – needs CA review") -> 0 | J9: =IF(D9=0,0,E9/D9) -> 0
B10: B. Statutory rules (law, rates, computations)
A11: 5 | B11: Income Tax | C11: Income-tax computation, rebate, rounding, presumptive taxation, disallowances, cash-transaction limits, capital gains. | D11: =COUNTA('Income Tax'!A6:A2000) -> 25 | E11: =COUNTIF('Income Tax'!E6:E2000,"Verified – official source") -> 13 | F11: =COUNTIF('Income Tax'!E6:E2000,"Verified – secondary source only") -> 1 | G11: =COUNTIF('Income Tax'!E6:E2000,"Partially verified") -> 11 | H11: =COUNTIF('Income Tax'!E6:E2000,"Unverified – needs CA review") -> 0 | I11: =COUNTIF('Income Tax'!E6:E2000,"Ambiguous / conflicting – needs CA review") -> 0 | J11: =IF(D11=0,0,E11/D11) -> 0.52
A12: 6 | B12: Advance Tax & Interest | C12: Advance tax liability, instalments, interest u/s 234A/234B/234C (new s.423/424/425), late fee. | D12: =COUNTA('Advance Tax & Interest'!A6:A2000) -> 8 | E12: =COUNTIF('Advance Tax & Interest'!E6:E2000,"Verified – official source") -> 7 | F12: =COUNTIF('Advance Tax & Interest'!E6:E2000,"Verified – secondary source only") -> 0 | G12: =COUNTIF('Advance Tax & Interest'!E6:E2000,"Partially verified") -> 1 | H12: =COUNTIF('Advance Tax & Interest'!E6:E2000,"Unverified – needs CA review") -> 0 | I12: =COUNTIF('Advance Tax & Interest'!E6:E2000,"Ambiguous / conflicting – needs CA review") -> 0 | J12: =IF(D12=0,0,E12/D12) -> 0.875
A13: 7 | B13: Returns & 26AS-AIS | C13: Return due dates, belated / revised / updated returns, 26AS / AIS / TIS, tax audit report. | D13: =COUNTA('Returns & 26AS-AIS'!A6:A2000) -> 7 | E13: =COUNTIF('Returns & 26AS-AIS'!E6:E2000,"Verified – official source") -> 1 | F13: =COUNTIF('Returns & 26AS-AIS'!E6:E2000,"Verified – secondary source only") -> 0 | G13: =COUNTIF('Returns & 26AS-AIS'!E6:E2000,"Partially verified") -> 4 | H13: =COUNTIF('Returns & 26AS-AIS'!E6:E2000,"Unverified – needs CA review") -> 1 | I13: =COUNTIF('Returns & 26AS-AIS'!E6:E2000,"Ambiguous / conflicting – needs CA review") -> 1 | J13: =IF(D13=0,0,E13/D13) -> 0.14285714
A14: 8 | B14: TDS | C14: TDS sections, thresholds, rates, due dates, interest, late fee, reconciliation (ss.192-206AA → ss.392-398). | D14: =COUNTA(TDS!A6:A2000) -> 49 | E14: =COUNTIF(TDS!E6:E2000,"Verified – official source") -> 28 | F14: =COUNTIF(TDS!E6:E2000,"Verified – secondary source only") -> 1 | G14: =COUNTIF(TDS!E6:E2000,"Partially verified") -> 17 | H14: =COUNTIF(TDS!E6:E2000,"Unverified – needs CA review") -> 3 | I14: =COUNTIF(TDS!E6:E2000,"Ambiguous / conflicting – needs CA review") -> 0 | J14: =IF(D14=0,0,E14/D14) -> 0.57142857
A15: 9 | B15: TCS | C15: TCS on goods, licences, motor vehicles / luxury goods, LRS, tour packages (s.206C → s.394). | D15: =COUNTA(TCS!A6:A2000) -> 9 | E15: =COUNTIF(TCS!E6:E2000,"Verified – official source") -> 6 | F15: =COUNTIF(TCS!E6:E2000,"Verified – secondary source only") -> 0 | G15: =COUNTIF(TCS!E6:E2000,"Partially verified") -> 3 | H15: =COUNTIF(TCS!E6:E2000,"Unverified – needs CA review") -> 0 | I15: =COUNTIF(TCS!E6:E2000,"Ambiguous / conflicting – needs CA review") -> 0 | J15: =IF(D15=0,0,E15/D15) -> 0.66666667
A16: 10 | B16: GST | C16: GSTIN, registration, place of supply, rates (GST 2.0), returns, ITC, reversals, RCM, interest, late fees, due dates. | D16: =COUNTA(GST!A6:A2000) -> 33 | E16: =COUNTIF(GST!E6:E2000,"Verified – official source") -> 6 | F16: =COUNTIF(GST!E6:E2000,"Verified – secondary source only") -> 5 | G16: =COUNTIF(GST!E6:E2000,"Partially verified") -> 21 | H16: =COUNTIF(GST!E6:E2000,"Unverified – needs CA review") -> 1 | I16: =COUNTIF(GST!E6:E2000,"Ambiguous / conflicting – needs CA review") -> 0 | J16: =IF(D16=0,0,E16/D16) -> 0.18181818
A17: 11 | B17: Payroll | C17: Labour Codes, EPF/EPS/EDLI, ESI, Professional Tax, LWF, gratuity, bonus, minimum wages, perquisites, s.36(1)(va). | D17: =COUNTA(Payroll!A6:A2000) -> 37 | E17: =COUNTIF(Payroll!E6:E2000,"Verified – official source") -> 12 | F17: =COUNTIF(Payroll!E6:E2000,"Verified – secondary source only") -> 9 | G17: =COUNTIF(Payroll!E6:E2000,"Partially verified") -> 14 | H17: =COUNTIF(Payroll!E6:E2000,"Unverified – needs CA review") -> 2 | I17: =COUNTIF(Payroll!E6:E2000,"Ambiguous / conflicting – needs CA review") -> 0 | J17: =IF(D17=0,0,E17/D17) -> 0.32432432
A18: 12 | B18: Bank Reconciliation | C18: Matching, classification, BRS statement, stale cheques. | D18: =COUNTA('Bank Reconciliation'!A6:A2000) -> 5 | E18: =COUNTIF('Bank Reconciliation'!E6:E2000,"Verified – official source") -> 1 | F18: =COUNTIF('Bank Reconciliation'!E6:E2000,"Verified – secondary source only") -> 3 | G18: =COUNTIF('Bank Reconciliation'!E6:E2000,"Partially verified") -> 1 | H18: =COUNTIF('Bank Reconciliation'!E6:E2000,"Unverified – needs CA review") -> 0 | I18: =COUNTIF('Bank Reconciliation'!E6:E2000,"Ambiguous / conflicting – needs CA review") -> 0 | J18: =IF(D18=0,0,E18/D18) -> 0.2
A19: 13 | B19: Trial Balance | C19: Arithmetic, suspense, opening-balance continuity, ledger agreement, abnormal balances. | D19: =COUNTA('Trial Balance'!A6:A2000) -> 5 | E19: =COUNTIF('Trial Balance'!E6:E2000,"Verified – official source") -> 0 | F19: =COUNTIF('Trial Balance'!E6:E2000,"Verified – secondary source only") -> 4 | G19: =COUNTIF('Trial Balance'!E6:E2000,"Partially verified") -> 1 | H19: =COUNTIF('Trial Balance'!E6:E2000,"Unverified – needs CA review") -> 0 | I19: =COUNTIF('Trial Balance'!E6:E2000,"Ambiguous / conflicting – needs CA review") -> 0 | J19: =IF(D19=0,0,E19/D19) -> 0
A20: 14 | B20: Ledger Scrutiny | C20: Cash scrutiny and limits, analytics, duplicates, dates, related parties, GST/TDS on expenses, ageing, confirmations. | D20: =COUNTA('Ledger Scrutiny'!A6:A2000) -> 14 | E20: =COUNTIF('Ledger Scrutiny'!E6:E2000,"Verified – official source") -> 0 | F20: =COUNTIF('Ledger Scrutiny'!E6:E2000,"Verified – secondary source only") -> 3 | G20: =COUNTIF('Ledger Scrutiny'!E6:E2000,"Partially verified") -> 5 | H20: =COUNTIF('Ledger Scrutiny'!E6:E2000,"Unverified – needs CA review") -> 6 | I20: =COUNTIF('Ledger Scrutiny'!E6:E2000,"Ambiguous / conflicting – needs CA review") -> 0 | J20: =IF(D20=0,0,E20/D20) -> 0
A21: 15 | B21: Financial Statements | C21: Schedule III classification, ageing, ratios, rounding, inventory reconciliation. | D21: =COUNTA('Financial Statements'!A6:A2000) -> 7 | E21: =COUNTIF('Financial Statements'!E6:E2000,"Verified – official source") -> 0 | F21: =COUNTIF('Financial Statements'!E6:E2000,"Verified – secondary source only") -> 1 | G21: =COUNTIF('Financial Statements'!E6:E2000,"Partially verified") -> 5 | H21: =COUNTIF('Financial Statements'!E6:E2000,"Unverified – needs CA review") -> 0 | I21: =COUNTIF('Financial Statements'!E6:E2000,"Ambiguous / conflicting – needs CA review") -> 1 | J21: =IF(D21=0,0,E21/D21) -> 0
A22: 16 | B22: MSME | C22: Classification, MSMED Act s.15/16 interest, MSME Form 1, s.43B(h). | D22: =COUNTA(MSME!A6:A2000) -> 4 | E22: =COUNTIF(MSME!E6:E2000,"Verified – official source") -> 1 | F22: =COUNTIF(MSME!E6:E2000,"Verified – secondary source only") -> 0 | G22: =COUNTIF(MSME!E6:E2000,"Partially verified") -> 3 | H22: =COUNTIF(MSME!E6:E2000,"Unverified – needs CA review") -> 0 | I22: =COUNTIF(MSME!E6:E2000,"Ambiguous / conflicting – needs CA review") -> 0 | J22: =IF(D22=0,0,E22/D22) -> 0.25
A23: 17 | B23: Company Law (MCA) | C23: Annual filings, other forms, late fees, small-company classification. | D23: =COUNTA('Company Law (MCA)'!A6:A2000) -> 4 | E23: =COUNTIF('Company Law (MCA)'!E6:E2000,"Verified – official source") -> 1 | F23: =COUNTIF('Company Law (MCA)'!E6:E2000,"Verified – secondary source only") -> 1 | G23: =COUNTIF('Company Law (MCA)'!E6:E2000,"Partially verified") -> 2 | H23: =COUNTIF('Company Law (MCA)'!E6:E2000,"Unverified – needs CA review") -> 0 | I23: =COUNTIF('Company Law (MCA)'!E6:E2000,"Ambiguous / conflicting – needs CA review") -> 0 | J23: =IF(D23=0,0,E23/D23) -> 0.25
A24: 18 | B24: Audit | C24: Audit trail, CARO 2020, tax audit, depreciation, accounting framework, Act transition. | D24: =COUNTA(Audit!A6:A2000) -> 7 | E24: =COUNTIF(Audit!E6:E2000,"Verified – official source") -> 0 | F24: =COUNTIF(Audit!E6:E2000,"Verified – secondary source only") -> 3 | G24: =COUNTIF(Audit!E6:E2000,"Partially verified") -> 4 | H24: =COUNTIF(Audit!E6:E2000,"Unverified – needs CA review") -> 0 | I24: =COUNTIF(Audit!E6:E2000,"Ambiguous / conflicting – needs CA review") -> 0 | J24: =IF(D24=0,0,E24/D24) -> 0
B25: Total rules | D25: =D6+D7+D8+D9+D11+D12+D13+D14+D15+D16+D17+D18+D19+D20+D21+D22+D23+D24 -> 304 | E25: =E6+E7+E8+E9+E11+E12+E13+E14+E15+E16+E17+E18+E19+E20+E21+E22+E23+E24 -> 77 | F25: =F6+F7+F8+F9+F11+F12+F13+F14+F15+F16+F17+F18+F19+F20+F21+F22+F23+F24 -> 43 | G25: =G6+G7+G8+G9+G11+G12+G13+G14+G15+G16+G17+G18+G19+G20+G21+G22+G23+G24 -> 158 | H25: =H6+H7+H8+H9+H11+H12+H13+H14+H15+H16+H17+H18+H19+H20+H21+H22+H23+H24 -> 24 | I25: =I6+I7+I8+I9+I11+I12+I13+I14+I15+I16+I17+I18+I19+I20+I21+I22+I23+I24 -> 2 | J25: =IF(D25=0,0,E25/D25) -> 0.25328947
B27: C. Data model & reference sheets
B28: Cover | C28: Title, research date, tax period, legend, disclaimer
B29: Document Pair Matrix | C29: Which documents each reconciliation rule compares – drives which files a client must upload
B30: Documents | C30: 63 documents with legal basis, formats, how obtained, due dates and the rules that use them
B31: Document Fields | C31: 2096 canonical fields (official labels, JSON paths, types, validations), incl. derived and design fields
B32: Field Map | C32: How each field reference in the rules resolves to a canonical field
B33: Act Transition | C33: Income-tax Act 1961 → 2025 section and form map
B34: Calculators | C34: Eleven worked examples with live formulas and checks
B35: Review Register | C35: Every rule not fully verified on an official source, with sign-off columns
B36: Superseded Provisions | C36: Old vs new positions and effective dates
B37: Open Questions | C37: Unresolved points requiring CA or business decision
B38: Rule Sources | C38: 951 citations, one row per rule–source pair
B39: Sources Consulted | C39: 501 pages consulted
... B41: Methodology | C41: Scope, rounds, source hierarchy, statuses, limitations

Sheet Recon – GST
A1: Recon – GST | AI1: ← Contents
A2: Document-to-document GST reconciliation: sales register / e-invoice / e-way bill vs GSTR-1 vs GSTR-3B; purchase register vs GSTR-2B / IMS vs 3B Table 4; ledgers, interest, late fee, annual return, rate and place-of-supply checks. Row 5 holds the YAML key for each column. Research date 13 October 2026. Every rule needs CA validation before use.
A3: Rules on sheet: | C3: =COUNTA(A6:A2000) -> 40
A4: Rule ID | B4: Rule type | C4: Category | D4: Rule name | E4: Verification status | F4: Purpose | G4: Document A | H4: Document B | I4: Document C | J4: Period basis | K4: Legal provision | L4: Applicability | M4: Effective from | N4: Effective to | O4: Prerequisites | P4: Match keys (A.field = B.field; canonical names) | Q4: Key normalisation | R4: Aggregation level | S4: Compare fields (A.field vs B.field) | T4: Tolerance | U4: Difference formula | V4: Step-by-step logic | W4: Mismatch categories (CODE: meaning) | X4: Severity by category | Y4: Editable parameters (key=value) | Z4: Input validations | AA4: Exception record output | AB4: Worked dataset & result | AC4: Positive test case(s) | AD4: Negative / edge test case(s) | AE4: Common real-world causes | AF4: Software action / remedy | AG4: Pseudocode | AH4: Sources (title | URL | ref, one per line) | AI4: Notes, verification, conflicts
A5: rule_id | B5: rule_type | C5: category | D5: name | E5: verification_status | F5: purpose | G5: doc_a | H5: doc_b | I5: doc_c | J5: period_basis | K5: legal_provision | L5: applicability | M5: effective_from | N5: effective_to | O5: prerequisites | P5: match_keys | Q5: key_normalisation | R5: aggregation | S5: compare_fields | T5: tolerance | U5: formula | V5: logic_steps | W5: mismatch_categories | X5: severity_by_category | Y5: params | Z5: validations | AA5: expected_output | AB5: sample_data_and_result | AC5: test_positive | AD5: test_negative | AE5: common_discrepancies | AF5: software_action | AG5: pseudocode | AH5: sources | AI5: notes
A6: RC-GST-001 | B6: reconciliation_rule | C6: GST – Outward supplies – Books vs return | D6: Sales register vs GSTR-1/IFF/GSTR-1A – B2B invoices (Table 4A/4B/4C, 6B, 6C) | E6: Partially verified | F6: Make sure every B2B tax invoice in the books is reported in GSTR-1, IFF or GSTR-1A for the right period, with the right GSTIN, value and tax heads, and that nothing is reported in the return that is not in the books. | G6: SALES_REG | H6: GSTR1 | I6: GSTR1A | J6: tax period (month); quarter for QRMP (IFF months 1-2 + GSTR-1 quarter) | K6: CGST Act s.37(1) (outward supply details), s.37(3) (rectification, time limit 30 Nov following FY or annual return, whichever earlier), s.37(5) (3-year bar, FA 2023 w.e.f. 01.10.2023 – N.28/2023-CT); CGST Rule 59 (GSTR-1, IFF); GSTR-1A inserted by N.12/2024-CT dt 10.07.2024 (optional, once per period, from July 2024 tax period); s.31 & Rule 46 (tax invoice contents, serial no. up to 16 characters unique for FY). | L6: All regular taxpayers filing GSTR-1 (monthly) or IFF + quarterly GSTR-1 (QRMP). B2B = supplies to GSTIN/UIN holders including SEZ (6B) and deemed exports (6C). | M6: 2017-07-01 | O6: Sales register for the period with document type, invoice no., date, buyer GSTIN, POS, taxable value, rate, IGST/CGST/SGST/cess, reverse-charge flag, SEZ/deemed-export flag. GSTR-1 JSON/Excel (b2b, sez, de sections) downloaded after filing; GSTR-1A JSON if filed; IFF JSON for QRMP months. | P6: SALES_REG.party_gstin = GSTR1.b2b_recipient_gstin; SALES_REG.voucher_no = GSTR1.b2b_invoice_no; SALES_REG.fy = fy(GSTR1.b2b_invoice_date) | Q6: Implementation choice: (1) Invoice/document number – uppercase, trim, collapse internal spaces, remove characters other than A-Z 0-9 '/' '-'; exact pass on this form. (2) Fuzzy pass key = strip '/', '-', spaces; strip leading zeros of each numeric run; strip common FY tokens (e.g. '2025-26', '25-26', '2526', 'FY26') – only if the remainder is still >= 3 characters. Law (Rule 46(b)) allows up to 16 characters, unique per FY. (3) GSTIN – uppercase, trim, validate 15-char pattern ^[0-9]{2}[A-Z]{5}[0-9]{4}[A-Z][1-9A-Z]Z[0-9A-Z]$ and check digit (see GST-001). (4) Dates – parse DD-MM-YYYY, DD/MM/YYYY, DD-MON-YY, YYYY-MM-DD, Excel serials into ISO date. (5) Amounts – Decimal, 2 dp, negative for credit notes only after doc-type mapping. Implementation choice: if the same normalised invoice no. appears for 2 buyers, match only with GSTIN; if buyer GSTIN differs but invoice no. + date + value agree, classify GSTIN_DIFF instead of two separate MISSING records. | R6: Invoice level. Sales register is item-wise – sum taxable value and each tax head per (buyer_gstin, invoice_no, rate) then per invoice. GSTR-1 b2b.inv.itms is rate-wise – sum to invoice. Merge GSTR-1 + GSTR-1A + IFF for the period; GSTR-1A record replaces the GSTR-1 record with the same key. | S6: SALES_REG.voucher_date vs GSTR1.b2b_invoice_date; SALES_REG.invoice_value vs GSTR1.b2b_invoice_value; SALES_REG.taxable_value vs GSTR1.b2b_taxable_value; SALES_REG.igst vs GSTR1.b2b_igst; SALES_REG.cgst vs GSTR1.b2b_cgst; SALES_REG.sgst_utgst vs GSTR1.b2b_sgst; SALES_REG.cess vs GSTR1.b2b_cess; SALES_REG.place_of_supply vs GSTR1.b2b_pos; SALES_REG.reverse_charge vs GSTR1.b2b_reverse_charge; SALES_REG.gst_rate vs GSTR1.b2b_rate | T6: Implementation choice (law prescribes none): Rs 1 per tax head per invoice and Rs 1 on taxable value (rounding, s.170 rounds only the final tax payable); date – exact; POS/rate/RCM flag – exact. CA may raise to Rs 10. | U6: diff_head = SALES_REG.head − GSTR1.head for head in (txval, iamt, camt, samt, csamt); value_mismatch if any |diff_head| > value_tolerance_inr; period_shift if month(SALES_REG.invoice_date) != GSTR1.return_period | V6: 1. Load sales register; keep doc_type in (Tax Invoice, SEZ with/without payment, Deemed export) and buyer GSTIN present. 2. Validate keys (see validations). 3. Aggregate both sides to invoice level. 4. Overlay GSTR-1A over GSTR-1 for the same period. 5. Pass 1 exact match on (GSTIN, normalised invoice no., FY). 6. Pass 2 fuzzy invoice no. within same GSTIN and FY, confirm with |value diff| <= tolerance and date diff <= date_window_days. 7. Pass 3 for unmatched: same invoice no.+date+value with different GSTIN -> GSTIN_DIFF. 8. For matched pairs compare fields; assign the most severe category per invoice and store one exception per differing field. 9. Search unmatched books invoices in GSTR-1 of other periods of the same FY and next FY up to the s.37(3) date -> PERIOD_SHIFT; else MISSING_IN_GSTR1. 10. Unmatched GSTR-1 records -> MISSING_IN_BOOKS. 11. Detect duplicates in each side (same key twice) -> DUPLICATE. 12. Totals: Σ books vs Σ GSTR-1 for the period must equal Σ(matched diff) + Σ(missing) – control check. | W6: MATCHED: all fields within tolerance; VALUE_DIFF: taxable value or invoice value differs; TAX_DIFF: one or more tax heads differ; HEAD_DIFF: IGST reported instead of CGST+SGST or vice versa (see RC-GST-034); RATE_DIFF: rate differs; POS_DIFF: place of supply differs; DATE_DIFF: date differs but same period; PERIOD_SHIFT: reported in another tax period; GSTIN_DIFF: same invoice reported against another GSTIN; INVNO_FORMAT: matched only on fuzzy key; RCM_FLAG_DIFF: reverse-charge flag differs; MISSING_IN_GSTR1: in books, not in any GSTR-1/1A/IFF; MISSING_IN_BOOKS: in GSTR-1 but not in books; DUPLICATE: same key appears more than once on one side; B2B_REPORTED_AS_B2C: books has GSTIN but return has it in B2CS/B2CL | X6: MATCHED=Low; INVNO_FORMAT=Low; DATE_DIFF=Low; VALUE_DIFF=High; TAX_DIFF=High; HEAD_DIFF=High; RATE_DIFF=High; POS_DIFF=High; PERIOD_SHIFT=Medium; GSTIN_DIFF=Critical; RCM_FLAG_DIFF=High; MISSING_IN_GSTR1=Critical; MISSING_IN_BOOKS=High; DUPLICATE=High; B2B_REPORTED_AS_B2C=Critical | Y6: value_tolerance_inr=1; tax_tolerance_inr=1; date_window_days=0; fuzzy_match=true; search_other_periods=true; include_gstr1a=true | Z6: Buyer GSTIN pattern + check digit; invoice no. <= 16 chars (Rule 46(b)) – warn if longer; invoice date within the period or earlier; taxable value >= 0 for invoices; IGST > 0 implies CGST=SGST=0 and vice versa; GSTR-1 file GSTIN and period equal the client's GSTIN and period being reconciled; file is the filed version (status 'Filed') not a draft. | AA6: exception_id; rule_id; client_id; gstin; period; doc_a_ref (file+row); doc_b_ref; match_key; match_pass (exact/fuzzy); category; severity; field_name; value_a; value_b; difference; tolerance_applied; suggested_action; legal_reference; status (Open/Under review/Resolved/Accepted-as-is); reviewer; review_comment; created_at; buyer_gstin; invoice_no_books; invoice_no_return; return_period_found; gstr1_or_1a_source | AB6: Books: (A) 27AAACX1234A1Z5 INV/001 05-08-2025 txval 1,00,000 CGST 9,000 SGST 9,000; (B) 29BBBCY5678B1Z2 INV/002 10-08-2025 txval 50,000 IGST 9,000; (C) 27AAACX1234A1Z5 INV/003 20-08-2025 txval 20,000 CGST 1,800 SGST 1,800; (D) 24CCCDZ9012C1Z8 INV/004 25-08-2025 txval 10,000 IGST 1,800. GSTR-1 Aug-2025: INV001 (27AAACX...) txval 1,00,000 C 9,000 S 9,000; INV/002 txval 50,000 IGST 8,100 (rate 18% vs 9,000 ⇒ 9,000−8,100 = 900); INV/004 not in Aug but in Sept GSTR-1. INV/005 27AAACX... txval 5,000 in GSTR-1 only. Result: A MATCHED (INVNO_FORMAT – 'INV/001' vs 'INV001' fuzzy); B TAX_DIFF IGST diff 900 > 1; C MISSING_IN_GSTR1 (tax 3,600 under-reported); D PERIOD_SHIFT (Aug -> Sep); INV/005 MISSING_IN_BOOKS (txval 5,000). | AC6: Books INV-10 txval 10,000.40 CGST 900.04 SGST 900.04 vs GSTR-1 INV-10 10,000 / 900 / 900 -> MATCHED (diffs 0.40, 0.04 within Rs 1). | AD6: Books invoice with buyer GSTIN '27AAACX1234A1Z0' (bad check digit) -> validation error, not matched; GSTR-1 file for another GSTIN -> rule aborts with INPUT_ERROR; books invoice no. 'INV-0007' and GSTR-1 '7' – fuzzy key '7' equals '7' but if value differs by Rs 5,000 -> not paired, both MISSING. | AE6: Invoice posted in books in a later month (back-dated); invoice cancelled in books but reported in GSTR-1; e-invoice auto-populated then edited; amendments filed in later GSTR-1 (B2BA) not overlaid; prefix/FY suffix differences between ERP and GSTR-1; buyer GSTIN changed (new registration/merger); SEZ invoices reported in B2B 4A instead of 6B; RCM supplies (4B) missed; IFF months not loaded for QRMP. | AF6: MISSING_IN_GSTR1 / TAX_DIFF (under-reported) for current period: report in GSTR-1A before filing GSTR-3B or in next GSTR-1 (B2B or B2BA) within s.37(3) time limit; if GSTR-3B already filed, pay differential via next 3B/DRC-03 with s.50 interest. MISSING_IN_BOOKS: check cancelled/duplicate invoice; amend via B2BA (reduce to nil) or issue credit note. GSTIN_DIFF: amend in B2BA – recipient's ITC is affected (Critical). Store with reviewer sign-off. | AG6: def rc_gst_001(books, g1, g1a, iff, p): ret = overlay(concat(g1, iff), g1a, key=['ctin','inum_n']) b = agg(books[books.doc_type.isin(B2B_TYPES)], ['buyer_gstin','inv_n','fy'], SUM_HEADS) r = agg(ret, ['ctin','inum_n','fy'], SUM_HEADS) pairs, ub, ur = match_exact(b, r, [('buyer_gstin','ctin'),('inv_n','inum_n'),('fy','fy')]) if p.fuzzy_match: pairs2, ub, ur = match_fuzzy(ub, ur, gstin_equal=True, key='inv_fz', confirm=lambda x,y: abs(x.txval-y.txval)<=p.value_tolerance_inr) pairs += tag(pairs2, 'INVNO_FORMAT') pairs3, ub, ur = match_on(ub, ur, ['inv_n','idt','txval']) # GSTIN_DIFF out = [] for a, x in pairs: for h in HEADS: d = a[h] - x[h] if abs(d) > p.tax_tolerance_inr: out.append(exc('TAX_DIFF' if h!='txval' else 'VALUE_DIFF', a, x, h, d)) for f in ('pos','rt','rchrg'): if a[f] != x[f]: out.append(exc(f.upper()+'_DIFF', a, x, f)) for a, x in pairs3: out.append(exc('GSTIN_DIFF', a, x)) for a in ub: hit = find_in_other_periods(a, all_returns_same_fy_and_next) out.append(exc('PERIOD_SHIFT' if hit else 'MISSING_IN_GSTR1', a, hit)) out += [exc('MISSING_IN_BOOKS', None, x) for x in ur] out += duplicates(b, 'DUPLICATE') + duplicates(r, 'DUPLICATE') return out | AH6: TaxGuru – Advisory on Form GSTR-1A | https://taxguru.in/goods-and-service-tax/advisory-form-gstr-1a.html | N.12/2024-CT; from July 2024 period; once per period; window till 3B filed; auto-populates 3B ClearTax – GST return filing rule changes from July 2025 | https://cleartax.in/s/gst-return-filing-rule-changes-from-july-2025 | GSTN advisories 07.06.2025 (3B Table 3 lock), 3-year bar Taxmann – returns cannot be filed after 3 years | https://www.taxmann.com/post/blog/gstn-warns-pending-gst-returns-cannot-be-filed-after-3-years | N.28/2023-CT; advisory 25.09.2025 | AI6: Matching keys, normalisation, tolerances and categories are implementation design. GSTR-1A start (July 2024 period, N.12/2024-CT) verified via TaxGuru reproduction of GSTN advisory. Field names follow the GSTR-1 offline JSON (ctin, inum, idt, val, pos, rchrg, itms.itm_det.txval/rt/iamt/camt/samt/csamt) as commonly published – confirm against the current GSTN API schema version. s.37(3) 30-Nov limit taken from GST-007 (statute knowledge, not re-opened).
A7: RC-GST-002 | B7: reconciliation_rule | C7: GST – Outward supplies – Books vs return | D7: Sales register vs GSTR-1 – B2C Large invoices (Table 5) | E7: Partially verified | F7: Check inter-state supplies to unregistered persons above the invoice-value threshold are reported invoice-wise in Table 5 (B2CL) with the correct POS and IGST, and are not lumped into B2CS. | G7: SALES_REG | H7: GSTR1 | J7: tax period (month) / quarter for QRMP | K7: CGST Act s.37; Rule 59(4) (invoice-wise details of inter-State supplies to unregistered persons above threshold); threshold reduced from Rs 2.5 lakh to Rs 1 lakh by N.12/2024-CT dt 10.07.2024 (GSTN advisory: portal change under development; till then continue reporting > Rs 2.5 lakh); IGST Act s.7 (inter-state), s.10 (POS goods). | L7: Suppliers making inter-state B2C supplies with invoice value above the threshold. | M7: 2024-07-10 | O7: Sales register with buyer GSTIN blank, POS state code, invoice value (incl. tax), IGST; GSTR-1 b2cl section (inum, idt, val, pos, itms). | P7: SALES_REG.voucher_no = GSTR1.b2cl_invoice_no; SALES_REG.place_of_supply = GSTR1.b2cl_pos | Q7: Implementation choice: (1) Invoice/document number – uppercase, trim, collapse internal spaces, remove characters other than A-Z 0-9 '/' '-'; exact pass on this form. (2) Fuzzy pass key = strip '/', '-', spaces; strip leading zeros of each numeric run; strip common FY tokens (e.g. '2025-26', '25-26', '2526', 'FY26') – only if the remainder is still >= 3 characters. Law (Rule 46(b)) allows up to 16 characters, unique per FY. (3) GSTIN – uppercase, trim, validate 15-char pattern ^[0-9]{2}[A-Z]{5}[0-9]{4}[A-Z][1-9A-Z]Z[0-9A-Z]$ and check digit (see GST-001). (4) Dates – parse DD-MM-YYYY, DD/MM/YYYY, DD-MON-YY, YYYY-MM-DD, Excel serials into ISO date. (5) Amounts – Decimal, 2 dp, negative for credit notes only after doc-type mapping. POS normalised to 2-digit state code (e.g. '29-Karnataka' -> '29'). | R7: Invoice level (sum items). Threshold test on invoice value including tax (Rule 59 refers to invoice value). | S7: SALES_REG.invoice_value vs GSTR1.b2cl_invoice_value; SALES_REG.taxable_value vs GSTR1.b2cl_taxable_value; SALES_REG.igst vs GSTR1.b2cl_igst; SALES_REG.place_of_supply vs GSTR1.b2cl_pos; SALES_REG.voucher_date vs GSTR1.b2cl_invoice_date | T7: Rs 1 per head (implementation choice); threshold comparison exact (strictly greater than threshold). | U7: b2cl_candidate = (buyer_gstin is blank) and (supplier_state != pos) and (invoice_value > b2cl_threshold_inr); expected_section = 'B2CL' if b2cl_candidate else 'B2CS' | V7: 1. Filter books: unregistered buyer, inter-state (POS != supplier state), not export. 2. Flag b2cl_candidate using threshold param (default Rs 1,00,000; switch to 2,50,000 if the CA confirms the portal still uses the old limit for the period). 3. Match candidates to GSTR-1 b2cl by normalised invoice no. 4. Compare fields. 5. Unmatched candidates: check if the value is included in B2CS for the same POS/rate (RC-GST-003) -> REPORTED_IN_B2CS; else MISSING_IN_GSTR1. 6. GSTR-1 b2cl records below threshold or intra-state -> WRONG_SECTION. 7. GSTR-1 b2cl records not in books -> MISSING_IN_BOOKS. | W7: MATCHED: agrees; VALUE_DIFF: value differs; TAX_DIFF: IGST differs; POS_DIFF: POS differs; REPORTED_IN_B2CS: candidate reported in B2CS summary instead of Table 5; WRONG_SECTION: below threshold or intra-state in B2CL; MISSING_IN_GSTR1: not reported anywhere; MISSING_IN_BOOKS: in GSTR-1 only | X7: MATCHED=Low; VALUE_DIFF=High; TAX_DIFF=High; POS_DIFF=Critical; REPORTED_IN_B2CS=Medium; WRONG_SECTION=Low; MISSING_IN_GSTR1=Critical; MISSING_IN_BOOKS=High | Y7: b2cl_threshold_inr=100000; value_tolerance_inr=1; threshold_basis=invoice_value_incl_tax | Z7: POS present and valid state code (01-38, 97); supplier state code from client GSTIN; buyer GSTIN blank (if present, route to RC-GST-001). | AA7: exception_id; rule_id; client_id; gstin; period; doc_a_ref (file+row); doc_b_ref; match_key; match_pass (exact/fuzzy); category; severity; field_name; value_a; value_b; difference; tolerance_applied; suggested_action; legal_reference; status (Open/Under review/Resolved/Accepted-as-is); reviewer; review_comment; created_at; pos; invoice_value; threshold_used; section_found | AB7: Supplier state 27. Books: (A) INV-50 POS 29 value 1,18,000 (txval 1,00,000 IGST 18,000); (B) INV-51 POS 33 value 59,000; (C) INV-52 POS 27 value 2,36,000 (intra-state). GSTR-1 b2cl: none; b2cs POS 29 18% txval 1,50,000. Threshold 1,00,000: A 1,18,000 > 1,00,000 and inter-state -> candidate; found inside B2CS POS 29 -> REPORTED_IN_B2CS. B 59,000 < 1,00,000 -> not candidate (B2CS). C intra-state -> not candidate. | AC7: Invoice POS 07, supplier 27, value 3,00,000, in GSTR-1 b2cl with same values -> MATCHED. | AD7: Invoice value exactly 1,00,000 -> not > threshold -> B2CS, no exception. Invoice with POS '96' (foreign) -> export, routed to RC-GST-004. | AE7: ERP still uses Rs 2.5 lakh threshold; POS taken as billing address instead of delivery address (s.10(1)(a)); invoices to unregistered SEZ/foreign treated as B2CL; B2CL reported in B2CS to save effort. | AF7: REPORTED_IN_B2CS: amend B2CS (Table 10) and report in Table 5/9A in next GSTR-1 – tax unchanged, disclosure only. POS_DIFF: correct POS via amendment; if wrong state got tax, tax may have to be paid to the correct state (IGST s.19/CGST s.77 refund route) – CA review. | AG7: def rc_gst_002(books, g1, p): sup_state = p.client_gstin[:2] c = books[(books.buyer_gstin=='') & (books.pos!=sup_state) & (books.pos!='96')] c = agg(c, ['inv_n','pos'], SUM_HEADS) c['cand'] = c.invoice_value > p.b2cl_threshold_inr pairs, ub, ur = match_exact(c[c.cand], g1.b2cl, [('inv_n','inum_n')]) out = compare(pairs, ['val','txval','iamt','pos'], p.value_tolerance_inr) for a in ub: out.append(exc('REPORTED_IN_B2CS' if in_b2cs(g1, a.pos, a.rate) else 'MISSING_IN_GSTR1', a)) for x in g1.b2cl: if x.val <= p.b2cl_threshold_inr or x.pos == sup_state: out.append(exc('WRONG_SECTION', None, x)) out += [exc('MISSING_IN_BOOKS', None, x) for x in ur if not any(i.inum_n==x.inum_n for i in books_all)] return out | AH7: TaxHeal – GSTN advisory on reporting supplies to unregistered dealers in GSTR-1/GSTR-5 | https://www.taxheal.com/?p=96273 | N.12/2024-CT dt 10.07.2024: invoice-wise threshold for inter-state B2C reduced Rs 2.5 lakh -> Rs 1 lakh; Table 5 | AI7: N.12/2024-CT reduction to Rs 1 lakh verified via TaxHeal reproduction of GSTN advisory; the advisory said portal changes were under development and asked taxpayers to continue with Rs 2.5 lakh till then – date from which the portal enforces Rs 1 lakh not confirmed, hence the threshold is a CA-editable param. Whether the threshold is on invoice value incl. tax (as in old Table 5 heading) should be confirmed by CA.
A8: RC-GST-003 | B8: reconciliation_rule | C8: GST – Outward supplies – Books vs return | D8: Sales register vs GSTR-1 – B2C Small summary (Table 7) by POS and rate | E8: Unverified – needs CA review | F8: Reconcile consolidated B2C (other than B2CL) supplies by place of supply, rate and type (intra/inter), including ECO-routed supplies. | G8: SALES_REG | H8: GSTR1 | J8: tax period (month) / quarter for QRMP | K8: CGST Act s.37; Rule 59(4)(b) (consolidated details of intra-state and inter-state B2C supplies by rate and state); Table 10 for amendments. | L8: All suppliers with B2C supplies (intra-state any value; inter-state up to B2CL threshold). | M8: 2017-07-01 | O8: Sales register B2C lines with POS and rate; credit notes to unregistered persons (domestic) are netted in B2CS per GSTN practice; GSTR-1 b2cs section (sply_ty INTRA/INTER, pos, rt, typ OE/E, etin). | P8: SALES_REG.place_of_supply = GSTR1.b2cs_pos; SALES_REG.gst_rate = GSTR1.b2cs_rate; SALES_REG.supply_type = GSTR1.b2cs_supply_type; SALES_REG.ecom_gstin = GSTR1.b2cs_ecom_gstin | Q8: POS to 2-digit code; rate to decimal with 2 dp (e.g. '18%' -> 18.00); supply_type derived (POS == supplier state -> INTRA). ECO GSTIN uppercase or blank. Implementation choice. | R8: Sum taxable value and each tax head by (pos, rate, supply_type, etin) for B2C invoices not in B2CL, net of domestic B2C credit notes and Table 10 amendments of the period. | S8: SALES_REG.Σ taxable_value by (pos, gst_rate, supply_type, ecom_gstin) for B2CS rows vs GSTR1.b2cs_taxable_value; SALES_REG.sum_igst vs GSTR1.b2cs_igst; SALES_REG.sum_cgst vs GSTR1.b2cs_cgst; SALES_REG.sum_sgst vs GSTR1.b2cs_sgst; SALES_REG.sum_cess vs GSTR1.b2cs_cess | T8: Rs 10 per (pos, rate) bucket – implementation choice (B2C lines accumulate rounding). | U8: diff = Σ_books(bucket) − Σ_gstr1(bucket); ratio = diff / Σ_books(bucket) | V8: 1. Exclude B2CL candidates (RC-GST-002 output). 2. Subtract domestic credit notes to unregistered persons in the bucket. 3. Group both sides. 4. Full outer join on bucket key. 5. Compare; buckets only on one side -> MISSING. 6. Also compare grand totals across all buckets – if totals agree but buckets differ -> RATE_OR_POS_SHIFT. | W8: MATCHED: bucket agrees; VALUE_DIFF: taxable differs; TAX_DIFF: tax differs; MISSING_IN_GSTR1: bucket in books only; MISSING_IN_BOOKS: bucket in return only; RATE_OR_POS_SHIFT: totals agree but distribution across POS/rate differs | X8: MATCHED=Low; VALUE_DIFF=High; TAX_DIFF=High; MISSING_IN_GSTR1=Critical; MISSING_IN_BOOKS=Medium; RATE_OR_POS_SHIFT=Medium | Y8: bucket_tolerance_inr=10; net_b2c_credit_notes=true | Z8: Every B2C line has POS and rate; rate in allowed list from rate master; INTRA buckets have CGST=SGST and IGST=0. | AA8: exception_id; rule_id; client_id; gstin; period; doc_a_ref (file+row); doc_b_ref; match_key; match_pass (exact/fuzzy); category; severity; field_name; value_a; value_b; difference; tolerance_applied; suggested_action; legal_reference; status (Open/Under review/Resolved/Accepted-as-is); reviewer; review_comment; created_at; pos; rate; supply_type; etin | AB8: Supplier state 27. Books B2C: POS 27 @18% txval 4,00,000 (C 36,000 S 36,000); POS 27 @5% txval 1,00,000 (C 2,500 S 2,500); POS 29 @18% txval 60,000 (IGST 10,800). GSTR-1 B2CS: 27/18 txval 4,00,000; 27/5 txval 90,000; 29/18 nil; 24/18 txval 60,000 IGST 10,800. Result: 27/18 MATCHED; 27/5 VALUE_DIFF 10,000 (tax 500); 29/18 MISSING_IN_GSTR1 and 24/18 MISSING_IN_BOOKS -> totals equal for inter-state 18% -> RATE_OR_POS_SHIFT (POS wrongly reported 24 instead of 29). | AC8: Books 27/18 txval 1,00,000.30; GSTR-1 1,00,000 -> MATCHED. | AD8: Books line with rate 12% dated 30-09-2025 for an item moved to 5% from 22-09-2025 -> also raises RC-GST-033 rate exception; here only bucket comparison. | AE8: POS wrong for online sales (billing vs shipping address); ECO supplies reported without ETIN or vice versa; credit notes to unregistered not netted; cash sales posted late. | AF8: Report differences via Table 10 (B2CS amendment) in next GSTR-1 within s.37(3) limit; short-reported tax to be paid in GSTR-3B/DRC-03 with interest. | AG8: def rc_gst_003(books, g1, b2cl_ids, p): b = books[(books.buyer_gstin=='') & (~books.inv_n.isin(b2cl_ids)) & (books.pos!='96')] b = b.assign(sply_ty=np.where(b.pos==p.client_gstin[:2],'INTRA','INTER')) kb = agg(b, ['pos','rate','sply_ty','etin'], SUM_HEADS) kr = agg(g1.b2cs, ['pos','rt','sply_ty','etin'], SUM_HEADS) j = outer_join(kb, kr) out = [] for row in j: if row.only_left: out.append(exc('MISSING_IN_GSTR1', row)) elif row.only_right: out.append(exc('MISSING_IN_BOOKS', row)) else: for h in HEADS: if abs(row[h+'_a']-row[h+'_b']) > p.bucket_tolerance_inr: out.append(exc('TAX_DIFF' if h!='txval' else 'VALUE_DIFF', row, field=h)) if abs(kb.txval.sum()-kr.txval.sum()) <= p.bucket_tolerance_inr and any(o.cat.startswith('MISSING') for o in out): out.append(exc('RATE_OR_POS_SHIFT', None)) return out | AH8: TaxHeal – GSTN advisory on reporting supplies to unregistered dealers in GSTR-1/GSTR-5 | https://www.taxheal.com/?p=96273 | N.12/2024-CT dt 10.07.2024: invoice-wise threshold for inter-state B2C reduced Rs 2.5 lakh -> Rs 1 lakh; Table 5 | AI8: Implementation design. GSTR-1 b2cs JSON fields (sply_ty, pos, rt, typ, etin, txval, iamt, camt, samt, csamt) are from the published offline-tool schema as commonly known – not opened in this session. Treatment of domestic B2C credit notes (netting in Table 7 vs CDNUR) is GSTN portal practice – CA to confirm.
A9: RC-GST-004 | B9: reconciliation_rule | C9: GST – Outward supplies – Zero-rated | D9: Sales register / shipping bills vs GSTR-1 – exports (Table 6A) and SEZ/deemed exports (6B/6C) | E9: Unverified – needs CA review | F9: Confirm export invoices are reported with correct export type (WPAY/WOPAY), shipping bill details, port code and IGST, so that IGST refund (WPAY) is not held up and LUT exports are not taxed. | G9: SALES_REG | H9: GSTR1 | I9: GSTR3B | J9: tax period (month) | K9: IGST Act s.16 (zero-rated supply; export under LUT or with payment of IGST and refund); CGST Rule 96 (refund of IGST paid on export – GSTR-1 Table 6A + shipping bill treated as refund application) and Rule 96A (LUT); CGST s.37; GSTR-3B Table 3.1(b). | L9: Exporters of goods/services and suppliers to SEZ units/developers; deemed exports. | M9: 2017-07-01 | O9: Sales register with export flag, export type, shipping bill no./date, port code, currency value, INR value, IGST; GSTR-1 exp section (exp_typ, inum, idt, val, sbpcode, sbnum, sbdt, itms); GSTR-3B 3.1(b). | P9: SALES_REG.voucher_no = GSTR1.exp_invoice_no; SALES_REG.fy = fy(GSTR1.exp_invoice_date) | Q9: Implementation choice: (1) Invoice/document number – uppercase, trim, collapse internal spaces, remove characters other than A-Z 0-9 '/' '-'; exact pass on this form. (2) Fuzzy pass key = strip '/', '-', spaces; strip leading zeros of each numeric run; strip common FY tokens (e.g. '2025-26', '25-26', '2526', 'FY26') – only if the remainder is still >= 3 characters. Law (Rule 46(b)) allows up to 16 characters, unique per FY. (3) GSTIN – uppercase, trim, validate 15-char pattern ^[0-9]{2}[A-Z]{5}[0-9]{4}[A-Z][1-9A-Z]Z[0-9A-Z]$ and check digit (see GST-001). (4) Dates – parse DD-MM-YYYY, DD/MM/YYYY, DD-MON-YY, YYYY-MM-DD, Excel serials into ISO date. (5) Amounts – Decimal, 2 dp, negative for credit notes only after doc-type mapping. Shipping bill no. – digits only; port code – uppercase 6 chars (e.g. INNSA1). | R9: Invoice level for 6A/6B/6C; period total for 3.1(b). | S9: SALES_REG.export_type vs GSTR1.exp_type; SALES_REG.taxable_value vs GSTR1.exp_taxable_value (6A) + b2b_taxable_value where b2b_invoice_type in SEWP/SEWOP/DE (6B/6C); SALES_REG.igst vs GSTR1.exp_igst (6A) + b2b_igst where b2b_invoice_type in SEWP/DE; SALES_REG.shipping_bill_no vs GSTR1.exp_shipping_bill_no; SALES_REG.shipping_bill_date vs GSTR1.exp_shipping_bill_date; SALES_REG.port_code vs GSTR1.exp_port_code; Σ(GSTR1 6A+6B+6C txval) vs GSTR3B.3_1_b.txval; Σ(6A+6B+6C iamt) vs GSTR3B.3_1_b.iamt | T9: Rs 1 per head per invoice; Rs 10 on period totals (implementation choice). Shipping bill fields exact. | U9: period_diff = Σ_gstr1_zero_rated − GSTR3B_3_1_b; wopay_tax_error = export_type=='WOPAY' and igst>0 | V9: 1. Match invoices. 2. Compare fields. 3. WOPAY with IGST > 0 or WPAY with IGST = 0 -> TYPE_TAX_CONFLICT. 4. Goods exports with blank shipping bill in GSTR-1 at filing -> SB_MISSING (may be added via amendment 9A). 5. Totals vs 3.1(b). 6. Service exports: no SB; check realisation is outside this rule. | W9: MATCHED: agrees; VALUE_DIFF: value differs; TAX_DIFF: IGST differs; TYPE_TAX_CONFLICT: export type inconsistent with IGST; SB_MISSING: shipping bill/port missing for goods; SB_DIFF: SB no./date/port differs; MISSING_IN_GSTR1; MISSING_IN_BOOKS; TOTAL_3B_DIFF: GSTR-1 zero-rated totals differ from 3B 3.1(b) | X9: MATCHED=Low; VALUE_DIFF=High; TAX_DIFF=High; TYPE_TAX_CONFLICT=Critical; SB_MISSING=High; SB_DIFF=High; MISSING_IN_GSTR1=Critical; MISSING_IN_BOOKS=High; TOTAL_3B_DIFF=High | Y9: value_tolerance_inr=1; total_tolerance_inr=10 | Z9: Exchange rate used is present; SB date >= invoice date; port code 6 characters; export type in (WPAY, WOPAY). | AA9: exception_id; rule_id; client_id; gstin; period; doc_a_ref (file+row); doc_b_ref; match_key; match_pass (exact/fuzzy); category; severity; field_name; value_a; value_b; difference; tolerance_applied; suggested_action; legal_reference; status (Open/Under review/Resolved/Accepted-as-is); reviewer; review_comment; created_at; export_type; sb_no; sb_date; port_code | AB9: Books: E-1 WPAY txval 5,00,000 IGST 90,000 SB 1234567 dt 12-08-2025 INNSA1; E-2 WOPAY txval 3,00,000 IGST 0 SB 1234570; E-3 WOPAY txval 2,00,000 (services). GSTR-1 6A: E-1 SB 1234567 but port INMAA1 -> SB_DIFF; E-2 IGST 54,000 -> TYPE_TAX_CONFLICT; E-3 matched. GSTR-3B 3.1(b) txval 10,00,000 = 5+3+2 lakh -> OK; IGST 1,44,000 vs GSTR-1 1,44,000 OK. | AC9: WPAY invoice with all SB fields equal -> MATCHED. | AD9: Goods export under WOPAY with SB filled later in 9A amendment -> after overlay of amendments, MATCHED (no SB_MISSING). | AE9: SB number entered after GSTR-1 filing; port code mismatch with ICEGATE causing refund errors; INR value at different exchange rate in books vs SB; deemed exports reported as B2B. | AF9: SB_DIFF / SB_MISSING for WPAY: amend Table 9A promptly – IGST refund under Rule 96 depends on matching with ICEGATE. TYPE_TAX_CONFLICT: CA review; LUT validity for the FY must be checked. | AG9: def rc_gst_004(books, g1, g3b, p): exp = overlay(g1.exp, g1.exp_amend, key=['inum_n']) pairs, ub, ur = match_exact(agg(books[books.is_export], ['inv_n','fy']), exp, [('inv_n','inum_n'),('fy','fy')]) out = compare(pairs, ['txval','iamt','sbnum','sbdt','sbpcode','exp_typ'], p.value_tolerance_inr) for a, x in pairs: if (x.exp_typ=='WOPAY' and x.iamt>0) or (x.exp_typ=='WPAY' and x.iamt==0): out.append(exc('TYPE_TAX_CONFLICT', a, x)) if a.is_goods and not x.sbnum: out.append(exc('SB_MISSING', a, x)) tot = sum_heads(exp) + sum_heads(g1.sez) + sum_heads(g1.de) if abs(tot.txval - g3b.t3_1_b.txval) > p.total_tolerance_inr: out.append(exc('TOTAL_3B_DIFF', tot, g3b.t3_1_b)) return out + missing(ub, ur) | AH9: GSTN advisory – auto-population of e-invoice details into GSTR-1 (ICMAI copy) | https://icmai.in/upload/Taxation/Advisory_auto-population_GSTR-1.pdf | B2B 4A/4B, EXP 6A, CDNR 9B, CDNUR(exports) auto-populated; edits blank the IRN; cancelled IRN deleted | AI9: Legal provisions (IGST s.16, Rule 96/96A) from statute knowledge – not re-opened in this session. Export invoices are auto-populated into 6A from e-invoices (GSTN advisory) – then SB details are added by the taxpayer.
A10: RC-GST-005 | B10: reconciliation_rule | C10: GST – Outward supplies – Credit/debit notes | D10: Books credit/debit notes vs GSTR-1 CDNR/CDNUR (Table 9B) | E10: Partially verified | F10: Check every credit and debit note issued in books is reported in GSTR-1 with correct GSTIN, note type, value and tax, within the s.34 time limit. | G10: SALES_REG | H10: GSTR1 | I10: GSTR1A | J10: tax period (month); time limit by FY of original supply | K10: CGST Act s.34(1)-(4) (credit/debit notes; s.34(2): CN to be declared not later than 30 November following end of FY or date of annual return, whichever earlier; proviso as amended by FA 2025 w.e.f. 01.10.2025 – no reduction of output tax unless recipient reverses ITC); s.37; Rule 53 (contents); GSTR-1 Table 9B. | L10: Suppliers issuing financial-with-GST credit notes or debit notes. | M10: 2017-07-01 | O10: Books CN/DN list with note no., date, type, original invoice no./date (optional in law but useful), party GSTIN, values; GSTR-1 cdnr (ctin, nt_num, nt_dt, ntty C/D, val, pos, itms) and cdnur (typ B2CL/EXPWP/EXPWOP). | P10: SALES_REG.party_gstin = GSTR1.cdnr_recipient_gstin; SALES_REG.voucher_no = GSTR1.cdnr_note_no; SALES_REG.note_type = GSTR1.cdnr_note_type | Q10: Implementation choice: (1) Invoice/document number – uppercase, trim, collapse internal spaces, remove characters other than A-Z 0-9 '/' '-'; exact pass on this form. (2) Fuzzy pass key = strip '/', '-', spaces; strip leading zeros of each numeric run; strip common FY tokens (e.g. '2025-26', '25-26', '2526', 'FY26') – only if the remainder is still >= 3 characters. Law (Rule 46(b)) allows up to 16 characters, unique per FY. (3) GSTIN – uppercase, trim, validate 15-char pattern ^[0-9]{2}[A-Z]{5}[0-9]{4}[A-Z][1-9A-Z]Z[0-9A-Z]$ and check digit (see GST-001). (4) Dates – parse DD-MM-YYYY, DD/MM/YYYY, DD-MON-YY, YYYY-MM-DD, Excel serials into ISO date. (5) Amounts – Decimal, 2 dp, negative for credit notes only after doc-type mapping. Note type mapped: Credit Note/CN/Sales Return -> C; Debit Note/DN/Supplementary invoice -> D (implementation choice: supplementary invoices raised as tax invoices go to RC-GST-001). | R10: Note level (sum rate-wise items). | S10: SALES_REG.voucher_date vs GSTR1.cdnr_note_date; SALES_REG.invoice_value vs GSTR1.cdnr_note_value; SALES_REG.taxable_value vs GSTR1.cdnr_taxable_value; SALES_REG.igst vs GSTR1.cdnr_igst; SALES_REG.cgst vs GSTR1.cdnr_cgst; SALES_REG.sgst_utgst vs GSTR1.cdnr_sgst; SALES_REG.place_of_supply vs GSTR1.cdnr_pos | T10: Rs 1 per head (implementation choice). Time limit – exact date (legal). | U10: cn_deadline = min(date(fy_end_year_of_original_supply, 11, 30), gstr9_filing_date); late_cn = note_type=='C' and gstr1_filing_date_of_cn > cn_deadline | V10: 1. Match notes. 2. Compare fields. 3. For CNs determine FY of original supply (from linked invoice; if not linked, ask CA – flag LINK_MISSING). 4. If CN reported after cn_deadline -> CN_TIME_BARRED (tax reduction not permitted). 5. From 01.10.2025: check recipient reversal evidence (IMS status 'Accepted' via supplier dashboard or recipient confirmation) – see RC-GST-029. 6. Unmatched books notes -> MISSING_IN_GSTR1; unmatched return notes -> MISSING_IN_BOOKS. | W10: MATCHED; VALUE_DIFF; TAX_DIFF; TYPE_DIFF: credit vs debit swapped; MISSING_IN_GSTR1; MISSING_IN_BOOKS; CN_TIME_BARRED: CN declared after s.34(2) limit; LINK_MISSING: original invoice not identified; DUPLICATE | X10: MATCHED=Low; VALUE_DIFF=High; TAX_DIFF=High; TYPE_DIFF=Critical; MISSING_IN_GSTR1=High; MISSING_IN_BOOKS=High; CN_TIME_BARRED=Critical; LINK_MISSING=Low; DUPLICATE=High | Y10: value_tolerance_inr=1; gstr9_filing_date=; require_invoice_link=false | Z10: Note date >= original invoice date; CN value <= original invoice value (warn); GSTIN valid. | AA10: exception_id; rule_id; client_id; gstin; period; doc_a_ref (file+row); doc_b_ref; match_key; match_pass (exact/fuzzy); category; severity; field_name; value_a; value_b; difference; tolerance_applied; suggested_action; legal_reference; status (Open/Under review/Resolved/Accepted-as-is); reviewer; review_comment; created_at; note_type; original_invoice_no; original_fy; cn_deadline | AB10: FY 2024-25 supplies. Books: CN-1 27AAACX... dt 15-10-2025 txval 10,000 CGST 900 SGST 900 (orig INV/2024-25/100); CN-2 dt 10-12-2025 txval 5,000 IGST 900 (orig FY 2024-25); DN-1 dt 20-10-2025 txval 2,000. GSTR-1: CN-1 in Oct-2025 matched; CN-2 in Dec-2025 GSTR-1 filed 11-01-2026; GSTR-9 FY24-25 filed 28-11-2025 -> deadline min(30-11-2025, 28-11-2025)=28-11-2025 -> CN_TIME_BARRED; DN-1 not in GSTR-1 -> MISSING_IN_GSTR1 (tax 360 at 18% short). | AC10: CN for FY 2025-26 supply reported in GSTR-1 of Oct-2026 filed 11-11-2026, GSTR-9 not filed -> within 30-11-2026 -> no time-bar exception. | AD10: Commercial credit note without GST (no tax heads) -> excluded from this rule (not a s.34 note). | AE10: Financial credit notes booked with GST but not reported; sales returns booked as negative invoices; CN reported as CDNUR when buyer is registered; time-barred CNs for discounts given after year-end; post-01.10.2025 CNs where recipient did not reverse ITC. | AF10: MISSING_IN_GSTR1 (DN): report in next GSTR-1 and pay tax with interest. CN_TIME_BARRED: reverse the tax reduction (add back liability) – pay via DRC-03 with s.50 interest; commercial adjustment only. TYPE_DIFF: amend in 9C (CDNRA). | AG10: def rc_gst_005(books, g1_all, p): n = agg(books[books.doc_type.isin(['C','D'])], ['party_gstin','note_n','ntty'], SUM_HEADS) r = overlay(g1_all.cdnr, g1_all.cdnra, key=['ctin','nt_num_n']) pairs, ub, ur = match_exact(n, r, [('party_gstin','ctin'),('note_n','nt_num_n')]) out = compare(pairs, ['txval','iamt','camt','samt','ntty','pos'], p.value_tolerance_inr) for a, x in pairs: if a.ntty=='C': if not a.orig_fy: out.append(exc('LINK_MISSING', a, x)); continue dl = min(date(a.orig_fy_end.year, 11, 30), p.gstr9_filing_date or date.max) if x.filing_date > dl: out.append(exc('CN_TIME_BARRED', a, x, deadline=dl)) return out + missing(ub, ur) | AH10: TaxGuru – Finance Act 2025 GST amendments effective 01.10.2025 | https://taxguru.in/goods-and-service-tax/gst-amendments-finance-act-2025-effective-oct-1-2025-notified.html | N.16/2025-CT; s.34(2) proviso; s.38; s.39(1) EY alert – GSTN advisory on IMS changes (23.09.2025) | https://www.ey.com/en_in/technical/alerts-hub/2025/09/gstn-issues-advisory-on-the-changes-introduced-in-the-invoice-management-system | pending CN one period; ITC reversal declaration; from Oct 2025 period | AI10: FA 2025 s.34(2) proviso (recipient reversal) verified via TaxGuru summary (GST-028). 30-November limit from statute knowledge (FA 2022) – not re-opened. FA 2026 amendment to s.15(3)/s.34(1) – commencement unverified (see gst.json open questions).
A11: RC-GST-006 | B11: reconciliation_rule | C11: GST – Outward supplies – Amendments | D11: GSTR-1 amendments (B2BA/B2CLA/EXPA/CDNRA/B2CSA) vs books revisions and s.37(3) time limit | E11: Partially verified | F11: Check that amendments reported in GSTR-1/1A tie to an actual change in the books, and that no amendment is filed after the statutory time limit. | G11: GSTR1 | H11: SALES_REG | J11: FY of original invoice | K11: CGST Act s.37(3) (rectification of errors in GSTR-1: not after 30 November following end of FY or date of annual return, whichever earlier – FA 2022); GSTR-1 Tables 9A, 9C, 10; GSTR-1A (N.12/2024-CT) for same-period corrections; s.37(5) 3-year bar. | L11: All GSTR-1 filers. | M11: 2022-10-01 | O11: All GSTR-1 files of the FY and of the next FY up to the time limit (amendment sections); books audit trail / revision log (Rule 56(1) audit-trail requirement under Companies Act for companies – implementation input). | P11: GSTR1.amend_original_invoice_no = SALES_REG.original_invoice_no; GSTR1.b2b_invoice_no = SALES_REG.voucher_no; GSTR1.b2b_recipient_gstin = SALES_REG.party_gstin | Q11: Implementation choice: (1) Invoice/document number – uppercase, trim, collapse internal spaces, remove characters other than A-Z 0-9 '/' '-'; exact pass on this form. (2) Fuzzy pass key = strip '/', '-', spaces; strip leading zeros of each numeric run; strip common FY tokens (e.g. '2025-26', '25-26', '2526', 'FY26') – only if the remainder is still >= 3 characters. Law (Rule 46(b)) allows up to 16 characters, unique per FY. (3) GSTIN – uppercase, trim, validate 15-char pattern ^[0-9]{2}[A-Z]{5}[0-9]{4}[A-Z][1-9A-Z]Z[0-9A-Z]$ and check digit (see GST-001). (4) Dates – parse DD-MM-YYYY, DD/MM/YYYY, DD-MON-YY, YYYY-MM-DD, Excel serials into ISO date. (5) Amounts – Decimal, 2 dp, negative for credit notes only after doc-type mapping. | R11: Invoice level; latest amendment wins. | S11: GSTR1.b2b_taxable_value vs SALES_REG.taxable_value; GSTR1.b2b_igst/b2b_cgst/b2b_sgst/b2b_cess vs SALES_REG.igst/cgst/sgst_utgst/cess; GSTR1.b2b_recipient_gstin vs SALES_REG.party_gstin; GSTR1.amendment_filing_date vs amendment_deadline | T11: Rs 1 per head (implementation choice); time limit exact (legal). | U11: amendment_deadline = min(date(fy_end_year_of_original, 11, 30), gstr9_filing_date); late = amendment_filing_date > amendment_deadline | V11: 1. Collect amendment records from GSTR-1 of all periods after the original. 2. Link to original by (oinum, oidt, octin). 3. Compare amended values with final books values. 4. Flag late amendments. 5. Flag books revisions (value changed after original GSTR-1 filing) with no amendment -> AMENDMENT_MISSING (covered by RC-GST-001 rerun at FY level). | W11: MATCHED: amendment equals books final; AMEND_VALUE_DIFF: amended value differs from books; AMENDMENT_LATE: filed after s.37(3) limit; AMENDMENT_MISSING: books revised but no amendment; ORIGINAL_NOT_FOUND: amendment refers to an invoice not in original GSTR-1 | X11: MATCHED=Low; AMEND_VALUE_DIFF=High; AMENDMENT_LATE=Critical; AMENDMENT_MISSING=High; ORIGINAL_NOT_FOUND=Medium | Y11: gstr9_filing_date=; value_tolerance_inr=1 | Z11: Amendment original period earlier than amendment period; original invoice exists. | AA11: exception_id; rule_id; client_id; gstin; period; doc_a_ref (file+row); doc_b_ref; match_key; match_pass (exact/fuzzy); category; severity; field_name; value_a; value_b; difference; tolerance_applied; suggested_action; legal_reference; status (Open/Under review/Resolved/Accepted-as-is); reviewer; review_comment; created_at; original_period; amendment_period; amendment_deadline | AB11: FY 2024-25 invoice INV-77 txval 1,00,000 reported Jan-2025. Books revised to 90,000 (CN not issued; invoice revised). GSTR-1 Oct-2025 (filed 11-11-2025) B2BA INV-77 txval 90,000; GSTR-9 FY 2024-25 filed 20-11-2025 -> deadline 20-11-2025; filing 11-11-2025 <= deadline -> MATCHED. Another B2BA for INV-80 filed 11-12-2025 -> AMENDMENT_LATE. | AC11: Amendment within limit and values equal -> MATCHED. | AD11: Amendment only changes POS (no value) -> compare POS; no time-limit issue if filed in time. | AE11: Downward amendments used instead of CN to avoid recipient reversal; late amendments after GSTR-9 filed; GSTIN corrections done after 30 Nov. | AF11: AMENDMENT_LATE: CA review – downward amendment may not be legally effective; upward amendment tax remains payable. AMENDMENT_MISSING: report via B2BA within time limit. | AG11: def rc_gst_006(g1_all, books, p): am = latest(concat(g1_all.b2ba, g1_all.cdnra, g1_all.expa), key=['octin','oinum_n']) out = [] for x in am: o = find_original(g1_all, x.octin, x.oinum_n) if not o: out.append(exc('ORIGINAL_NOT_FOUND', None, x)); continue dl = min(date(fy_end(o.idt).year, 11, 30), p.gstr9_filing_date or date.max) if x.filing_date > dl: out.append(exc('AMENDMENT_LATE', o, x, deadline=dl)) b = books_final(books, x.ctin, x.inum_n) if b is not None and any(abs(b[h]-x[h])>p.value_tolerance_inr for h in HEADS): out.append(exc('AMEND_VALUE_DIFF', b, x)) return out | AH11: TaxGuru – Advisory on Form GSTR-1A | https://taxguru.in/goods-and-service-tax/advisory-form-gstr-1a.html | N.12/2024-CT; from July 2024 period; once per period; window till 3B filed; auto-populates 3B Taxmann – returns cannot be filed after 3 years | https://www.taxmann.com/post/blog/gstn-warns-pending-gst-returns-cannot-be-filed-after-3-years | N.28/2023-CT; advisory 25.09.2025 | AI11: s.37(3) 30-Nov limit from statute knowledge (FA 2022 amendment), consistent with GST-007; not re-opened. Implementation design for linking.
